Workbook

Sheet Messdaten
B1: p_d_em | C1: Sc/Rc | E1: p_a_em | F1: Sc/Rc | H1: p_d_ex | I1: Sc/Rc | K1: p_a_ex | L1: Sc/Rc | P1: D_em | Q1: Sc/Rc | S1: D_ex | T1: Sc/Rc | V1: A_em | W1: Sc/Rc | Y1: A_ex | Z1: Sc/Rc | AD1: HF_d_em | AE1: Sc/Rc | AG1: LF_d_em | AH1: Sc/Rc
B2: X | C2: Y | E2: X | F2: Y | H2: X | I2: Y | K2: X | L2: Y | P2: X | Q2: Y | S2: X | T2: Y | V2: X | W2: Y | Y2: X | Z2: Y | AD2: X | AE2: Y | AG2: X | AH2: Y
B3: 480 | C3: 2837.9165 | E3: 620 | F3: 671.35358 | H3: 400 | I3: 734.2155 | K3: 400 | L3: 894.09587 | P3: 480 | Q3: 2868.4257 | S3: 400 | T3: 3039.8657 | V3: 620 | W3: 1828.6869 | Y3: 400 | Z3: 1738.6593 | AD3: 480 | AE3: 2742.4301 | AG3: 480 | AH3: 3068.9351
B4: 481 | C4: 2031.2625 | E4: 621 | F4: 472.04137 | H4: 401 | I4: 730.68332 | K4: 401 | L4: 700.94892 | P4: 481 | Q4: 2638.4417 | S4: 401 | T4: 3183.8126 | V4: 621 | W4: 1882.5397 | Y4: 401 | Z4: 1938.639 | AD4: 481 | AE4: 2556.1594 | AG4: 481 | AH4: 2697.8084
B5: 482 | C5: 1571.7779 | E5: 622 | F5: 383.40219 | H5: 402 | I5: 691.85607 | K5: 402 | L5: 865.46125 | P5: 482 | Q5: 2626.5822 | S5: 402 | T5: 3227.2704 | V5: 622 | W5: 2067.0255 | Y5: 402 | Z5: 1839.8651 | AD5: 482 | AE5: 2523.6509 | AG5: 482 | AH5: 2594.6025
B6: 483 | C6: 1222.103 | E6: 623 | F6: 171.19154 | H6: 403 | I6: 714.90643 | K6: 403 | L6: 764.53823 | P6: 483 | Q6: 2853.9616 | S6: 403 | T6: 3228.3149 | V6: 623 | W6: 2390.7863 | Y6: 403 | Z6: 1742.4466 | AD6: 483 | AE6: 2730.0813 | AG6: 483 | AH6: 2862.5474
B7: 484 | C7: 1012.7859 | E7: 624 | F7: 288.78331 | H7: 404 | I7: 827.72498 | K7: 404 | L7: 769.52755 | P7: 484 | Q7: 3237.2829 | S7: 404 | T7: 3380.2192 | V7: 624 | W7: 2758.6793 | Y7: 404 | Z7: 1719.3574 | AD7: 484 | AE7: 3127.6198 | AG7: 484 | AH7: 3160.2716
B8: 485 | C8: 925.49835 | E8: 625 | F8: 209.7888 | H8: 405 | I8: 739.4734 | K8: 405 | L8: 797.49582 | P8: 485 | Q8: 3737.9331 | S8: 405 | T8: 3631.9104 | V8: 625 | W8: 3067.0211 | Y8: 405 | Z8: 1508.0923 | AD8: 485 | AE8: 3535.7994 | AG8: 485 | AH8: 3498.892
B9: 486 | C9: 773.55427 | E9: 626 | F9: 209.00739 | H9: 406 | I9: 652.59349 | K9: 406 | L9: 868.18159 | P9: 486 | Q9: 4534.5886 | S9: 406 | T9: 3895.7584 | V9: 626 | W9: 3598.7239 | Y9: 406 | Z9: 1474.2417 | AD9: 486 | AE9: 4352.5925 | AG9: 486 | AH9: 4173.6494
B10: 487 | C10: 711.93719 | E10: 627 | F10: 165.41504 | H10: 407 | I10: 701.3288 | K10: 407 | L10: 884.78133 | P10: 487 | Q10: 5457.2077 | S10: 407 | T10: 3897.7329 | V10: 627 | W10: 4169.6051 | Y10: 407 | Z10: 1232.8132 | AD10: 487 | AE10: 5117.7795 | AG10: 487 | AH10: 4927.7527
B11: 488 | C11: 699.16833 | E11: 628 | F11: 187.63436 | H11: 408 | I11: 755.9672 | K11: 408 | L11: 697.90614 | P11: 488 | Q11: 6462.4516 | S11: 408 | T11: 4156.3521 | V11: 628 | W11: 5160.78 | Y11: 408 | Z11: 1568.8737 | AD11: 488 | AE11: 6177.4397 | AG11: 488 | AH11: 5869.4886
B12: 489 | C12: 622.46473 | E12: 629 | F12: 290.0214 | H12: 409 | I12: 662.82445 | K12: 409 | L12: 857.55594 | P12: 489 | Q12: 7899.9339 | S12: 409 | T12: 4285.1992 | V12: 629 | W12: 5843.486 | Y12: 409 | Z12: 1447.5823 | AD12: 489 | AE12: 7256.2625 | AG12: 489 | AH12: 7176.8478
B13: 490 | C13: 573.88384 | E13: 630 | F13: 91.25248 | H13: 410 | I13: 639.667 | K13: 410 | L13: 941.36456 | P13: 490 | Q13: 9538.8171 | S13: 410 | T13: 4487.609 | V13: 630 | W13: 6896.8729 | Y13: 410 | Z13: 1087.218 | AD13: 490 | AE13: 8882.5542 | AG13: 490 | AH13: 8574.0515
B14: 491 | C14: 551.42654 | E14: 631 | F14: 35.01723 | H14: 411 | I14: 654.35346 | K14: 411 | L14: 791.33549 | P14: 491 | Q14: 11323.367 | S14: 411 | T14: 4713.8738 | V14: 631 | W14: 7875.2823 | Y14: 411 | Z14: 1393.1689 | AD14: 491 | AE14: 10511.577 | AG14: 491 | AH14: 10079.834
... B113: 590 | C113: 179.01693 | E113: 730 | F113: 115.07463 | H113: 510 | I113: 1840.9277 | K113: 510 | L113: 359.38751 | P113: 590 | Q113: 11487.039 | S113: 510 | T113: 68602.565 | V113: 730 | W113: 21269.186 | Y113: 510 | Z113: 8432.4402 | AD113: 590 | AE113: 8739.1788 | AG113: 590 | AH113: 8444.5209
B114: 591 | C114: 216.13719 | E114: 731 | F114: 148.19008 | K114: 511 | L114: 249.20429 | P114: 591 | Q114: 11509.746 | V114: 731 | W114: 20398.837 | Y114: 511 | Z114: 8350.9219 | AD114: 591 | AE114: 8540.8944 | AG114: 591 | AH114: 8316.4227
B115: 592 | C115: 186.29817 | E115: 732 | F115: 71.32979 | K115: 512 | L115: 383.18228 | P115: 592 | Q115: 10851.294 | V115: 732 | W115: 19567.739 | Y115: 512 | Z115: 9093.573 | AD115: 592 | AE115: 8101.1605 | AG115: 592 | AH115: 7856.5766
B116: 593 | C116: 241.16756 | E116: 733 | F116: 346.55733 | K116: 513 | L116: 210.9134 | P116: 593 | Q116: 10482.593 | V116: 733 | W116: 19804.683 | Y116: 513 | Z116: 8918.0604 | AD116: 593 | AE116: 7974.933 | AG116: 593 | AH116: 7721.0091
B117: 594 | C117: 203.01042 | E117: 734 | F117: 385.00261 | K117: 514 | L117: 425.62885 | P117: 594 | Q117: 10023.23 | V117: 734 | W117: 18991.751 | Y117: 514 | Z117: 9862.559 | AD117: 594 | AE117: 7466.2278 | AG117: 594 | AH117: 7333.4976
B118: 595 | C118: 219.38086 | E118: 735 | F118: 224.75191 | K118: 515 | L118: 339.92591 | P118: 595 | Q118: 9571.6624 | V118: 735 | W118: 17591.088 | Y118: 515 | Z118: 10145.062 | AD118: 595 | AE118: 7360.8111 | AG118: 595 | AH118: 7141.7742
B119: 596 | C119: 208.84683 | E119: 736 | F119: 76.22457 | K119: 516 | L119: 197.21356 | P119: 596 | Q119: 9362.6539 | V119: 736 | W119: 16932.709 | Y119: 516 | Z119: 10870.744 | AD119: 596 | AE119: 7249.4619 | AG119: 596 | AH119: 6914.8172
B120: 597 | C120: 224.28391 | E120: 737 | F120: 301.45512 | K120: 517 | L120: 558.15801 | P120: 597 | Q120: 8829.5382 | V120: 737 | W120: 16785.095 | Y120: 517 | Z120: 11084.842 | AD120: 597 | AE120: 6761.7477 | AG120: 597 | AH120: 6603.0726
B121: 598 | C121: 202.69964 | E121: 738 | F121: 323.5482 | K121: 518 | L121: 262.29282 | P121: 598 | Q121: 8746.5183 | V121: 738 | W121: 16768.903 | Y121: 518 | Z121: 11082.586 | AD121: 598 | AE121: 6616.4179 | AG121: 598 | AH121: 6614.6336
B122: 599 | C122: 165.1774 | E122: 739 | F122: 363.60565 | K122: 519 | L122: 327.46648 | P122: 599 | Q122: 8101.3585 | V122: 739 | W122: 16124.96 | Y122: 519 | Z122: 11772.145 | AD122: 599 | AE122: 6587.7899 | AG122: 599 | AH122: 6243.9588
B123: 600 | C123: 189.24034 | E123: 740 | F123: 693.60863 | K123: 520 | L123: 296.22173 | P123: 600 | Q123: 7916.4392 | V123: 740 | W123: 16441.412 | Y123: 520 | Z123: 12233.641 | AD123: 600 | AE123: 6285.896 | AG123: 600 | AH123: 6008.9379
B124: 601 | C124: 151.0066 | E124: 741 | F124: -27.42613 | K124: 521 | L124: 313.17671 | P124: 601 | Q124: 7770.4118 | V124: 741 | W124: 15718.481 | Y124: 521 | Z124: 12158.186 | AD124: 601 | AE124: 5995.24 | AG124: 601 | AH124: 5819.8962
B125: 602 | C125: 210.35972 | E125: 742 | F125: 83.38959 | K125: 522 | L125: 257.67296 | P125: 602 | Q125: 7525.0161 | V125: 742 | W125: 14314.442 | Y125: 522 | Z125: 13348.698 | AD125: 602 | AE125: 5706.4276 | AG125: 602 | AH125: 5540.6978
... B183: 660 | C183: 245.6793 | E183: 800 | F183: -174.76132 | K183: 580 | L183: 189.45334 | P183: 660 | Q183: 1086.6951 | V183: 800 | W183: 2771.3411 | Y183: 580 | Z183: 121633.52 | AD183: 660 | AE183: 41167.843 | AG183: 660 | AH183: 17431.296
B184: 661 | C184: 242.81844 | K184: 581 | L184: 295.1382 | P184: 661 | Q184: 1023.8426 | Y184: 581 | Z184: 126600.95 | AD184: 661 | AE184: 42719.068 | AG184: 661 | AH184: 17848.6
B185: 662 | C185: 245.93334 | K185: 582 | L185: 160.2063 | P185: 662 | Q185: 1009.9232 | Y185: 582 | Z185: 132630.86 | AD185: 662 | AE185: 43157.201 | AG185: 662 | AH185: 18061.107
B186: 663 | C186: 266.33824 | K186: 583 | L186: 73.77931 | P186: 663 | Q186: 1133.0388 | Y186: 583 | Z186: 139286.28 | AD186: 663 | AE186: 44025.626 | AG186: 663 | AH186: 18284.73
B187: 664 | C187: 225.62231 | K187: 584 | L187: 351.79372 | P187: 664 | Q187: 1127.7805 | Y187: 584 | Z187: 144627.02 | AD187: 664 | AE187: 44311.654 | AG187: 664 | AH187: 18490.61
B188: 665 | C188: 275.87927 | K188: 585 | L188: 179.87997 | P188: 665 | Q188: 1061.0271 | Y188: 585 | Z188: 151535.03 | AD188: 665 | AE188: 44328.594 | AG188: 665 | AH188: 18551.783
B189: 666 | C189: 309.60041 | K189: 586 | L189: 334.9788 | P189: 666 | Q189: 925.17317 | Y189: 586 | Z189: 156870.82 | AD189: 666 | AE189: 44387.009 | AG189: 666 | AH189: 18791.845
B190: 667 | C190: 221.94241 | K190: 587 | L190: 239.57165 | P190: 667 | Q190: 907.93604 | Y190: 587 | Z190: 162412.71 | AD190: 667 | AE190: 44688.938 | AG190: 667 | AH190: 18142.588
B191: 668 | C191: 233.89168 | K191: 588 | L191: 493.82737 | P191: 668 | Q191: 1002.4296 | Y191: 588 | Z191: 168228.78 | AD191: 668 | AE191: 43803.813 | AG191: 668 | AH191: 18271.396
B192: 669 | C192: 284.3009 | K192: 589 | L192: 310.93001 | P192: 669 | Q192: 869.81916 | Y192: 589 | Z192: 174050.95 | AD192: 669 | AE192: 42613.423 | AG192: 669 | AH192: 18190.987
B193: 670 | C193: 272.36121 | K193: 590 | L193: 204.91164 | P193: 670 | Q193: 862.64364 | Y193: 590 | Z193: 180294.84 | AD193: 670 | AE193: 42692.3 | AG193: 670 | AH193: 17462.726
B194: 671 | C194: 431.20177 | K194: 591 | L194: 147.06665 | P194: 671 | Q194: 846.75776 | Y194: 591 | Z194: 183967.6 | AD194: 671 | AE194: 40257.018 | AG194: 671 | AH194: 17018.656
B195: 672 | C195: 322.9672 | K195: 592 | L195: 290.76903 | P195: 672 | Q195: 810.86053 | Y195: 592 | Z195: 189632.01 | AD195: 672 | AE195: 39725.317 | AG195: 672 | AH195: 16587.139
...

Sheet Korrigiert
A1: D_em | B1: Sc/Rc | E1: D_ex | F1: Sc/Rc | I1: A_em | J1: Sc/Rc | M1: A_ex | N1: Sc/Rc | Q1: HF_d_em | R1: Sc/Rc | U1: LF_d_em | V1: Sc/Rc | Y1: lambda | Z1: J(lambda) | AA1: Fläche | AB1: J | AC1: R0
A2: X | B2: Korr | C2: Norm_max | D2: Norm_int | E2: X | F2: Korr | G2: Norm_max | H2: Norm_em | I2: X | J2: Korr | K2: Norm_max | L2: Norm_int | M2: X | N2: Korr | O2: Norm_max | P2: Norm_em | Q2: X | R2: Korr | S2: Norm_max | U2: X | V2: Korr | W2: Norm_max | Y2: =A3 -> 480 | Z2: =D3*P83*Y2^4 -> 2.1659744e+08 | AA2: =(Z2+Z3)/2*(Y3-Y2) -> 2.3065909e+09 | AB2: =SUM(AA:AA) -> 1.6021866e+15 | AC2: =0.218*(2/3*0.8*1.333^(-4)*AB2)^(1/6) -> 55.444061
A3: {=Messdaten!P3:P323} -> 480 | B3: =Messdaten!Q3-Messdaten!C3 -> 30.5092 | C3: =(B3-MIN(B:B))/(MAX(B:B)-MIN(B:B)) -> 0.0067703441 | D3: =B3/SUM(B:B) -> 5.1148022e-06 | E3: {=Messdaten!S3:S113} -> 400 | F3: =Messdaten!T3-Messdaten!I3 -> 2305.6502 | G3: =(F3-MIN(F:F))/(MAX(F:F)-MIN(F:F)) -> 0 | H3: =F3/MAX(F:F)*71000 -> 641.05256 | I3: {=Messdaten!V3:V183} -> 620 | J3: =Messdaten!W3-Messdaten!F3 -> 1157.3334 | K3: =(J3-MIN(J:J))/(MAX(J:J)-MIN(J:J)) -> 0 | L3: =J3/SUM(J:J) -> 0.00017980357 | M3: {=Messdaten!Y3:Y263} -> 400 | N3: =Messdaten!Z3-Messdaten!L3 -> 844.56341 | O3: =(N3-MIN(N:N))/(MAX(N:N)-MIN(N:N)) -> 0.0016598888 | P3: =N3/MAX(N:N)*250000 -> 307.00925 | Q3: {=Messdaten!AD3:AD323} -> 480 | R3: =Messdaten!AE3-Messdaten!C3 -> -95.48643 | S3: =(R3-MIN(R:R))/(MAX(R:R)-MIN(R:R)) -> 0.00046630558 | U3: {=Messdaten!AG3:AG323} -> 480 | V3: =Messdaten!AH3-Messdaten!C3 -> 231.01858 | W3: =(V3-MIN(V:V))/(MAX(V:V)-MIN(V:V)) -> 0.0072788607 | Y3: =A4 -> 481 | Z3: =D4*P84*Y3^4 -> 4.3965844e+09 | AA3: =(Z3+Z4)/2*(Y4-Y3) -> 5.827357e+09
A4: 481 | B4: =Messdaten!Q4-Messdaten!C4 -> 607.17923 | C4: =(B4-MIN(B:B))/(MAX(B:B)-MIN(B:B)) -> 0.011544282 | D4: =B4/SUM(B:B) -> 0.0001017923 | E4: 401 | F4: =Messdaten!T4-Messdaten!I4 -> 2453.1293 | G4: =(F4-MIN(F:F))/(MAX(F:F)-MIN(F:F)) -> 0.00058278895 | H4: =F4/MAX(F:F)*71000 -> 682.05698 | I4: 621 | J4: =Messdaten!W4-Messdaten!F4 -> 1410.4983 | K4: =(J4-MIN(J:J))/(MAX(J:J)-MIN(J:J)) -> 0.0018675996 | L4: =J4/SUM(J:J) -> 0.00021913534 | M4: 401 | N4: =Messdaten!Z4-Messdaten!L4 -> 1237.6901 | O4: =(N4-MIN(N:N))/(MAX(N:N)-MIN(N:N)) -> 0.0022312674 | P4: =N4/MAX(N:N)*250000 -> 449.91567 | Q4: 481 | R4: =Messdaten!AE4-Messdaten!C4 -> 524.8969 | S4: =(R4-MIN(R:R))/(MAX(R:R)-MIN(R:R)) -> 0.0064783261 | U4: 481 | V4: =Messdaten!AH4-Messdaten!C4 -> 666.54587 | W4: =(V4-MIN(V:V))/(MAX(V:V)-MIN(V:V)) -> 0.011625931 | Y4: =A5 -> 482 | Z4: =D5*P85*Y4^4 -> 7.2581295e+09 | AA4: =(Z4+Z5)/2*(Y5-Y4) -> 1.0793745e+10
A5: 482 | B5: =Messdaten!Q5-Messdaten!C5 -> 1054.8043 | C5: =(B5-MIN(B:B))/(MAX(B:B)-MIN(B:B)) -> 0.015249927 | D5: =B5/SUM(B:B) -> 0.00017683569 | E5: 402 | F5: =Messdaten!T5-Messdaten!I5 -> 2535.4144 | G5: =(F5-MIN(F:F))/(MAX(F:F)-MIN(F:F)) -> 0.00090795255 | H5: =F5/MAX(F:F)*71000 -> 704.93515 | I5: 622 | J5: =Messdaten!W5-Messdaten!F5 -> 1683.6233 | K5: =(J5-MIN(J:J))/(MAX(J:J)-MIN(J:J)) -> 0.0038824441 | L5: =J5/SUM(J:J) -> 0.0002615681 | M5: 402 | N5: =Messdaten!Z5-Messdaten!L5 -> 974.40384 | O5: =(N5-MIN(N:N))/(MAX(N:N)-MIN(N:N)) -> 0.0018486016 | P5: =N5/MAX(N:N)*250000 -> 354.20785 | Q5: 482 | R5: =Messdaten!AE5-Messdaten!C5 -> 951.87304 | S5: =(R5-MIN(R:R))/(MAX(R:R)-MIN(R:R)) -> 0.010616073 | U5: 482 | V5: =Messdaten!AH5-Messdaten!C5 -> 1022.8246 | W5: =(V5-MIN(V:V))/(MAX(V:V)-MIN(V:V)) -> 0.015182007 | Y5: =A6 -> 483 | Z5: =D6*P86*Y5^4 -> 1.4329361e+10 | AA5: =(Z5+Z6)/2*(Y6-Y5) -> 1.7053564e+10
A6: 483 | B6: =Messdaten!Q6-Messdaten!C6 -> 1631.8587 | C6: =(B6-MIN(B:B))/(MAX(B:B)-MIN(B:B)) -> 0.020027047 | D6: =B6/SUM(B:B) -> 0.00027357762 | E6: 403 | F6: =Messdaten!T6-Messdaten!I6 -> 2513.4085 | G6: =(F6-MIN(F:F))/(MAX(F:F)-MIN(F:F)) -> 0.00082099257 | H6: =F6/MAX(F:F)*71000 -> 698.81673 | I6: 623 | J6: =Messdaten!W6-Messdaten!F6 -> 2219.5948 | K6: =(J6-MIN(J:J))/(MAX(J:J)-MIN(J:J)) -> 0.0078363085 | L6: =J6/SUM(J:J) -> 0.00034483674 | M6: 403 | N6: =Messdaten!Z6-Messdaten!L6 -> 977.90839 | O6: =(N6-MIN(N:N))/(MAX(N:N)-MIN(N:N)) -> 0.0018536952 | P6: =N6/MAX(N:N)*250000 -> 355.4818 | Q6: 483 | R6: =Messdaten!AE6-Messdaten!C6 -> 1507.9783 | S6: =(R6-MIN(R:R))/(MAX(R:R)-MIN(R:R)) -> 0.016005187 | U6: 483 | V6: =Messdaten!AH6-Messdaten!C6 -> 1640.4444 | W6: =(V6-MIN(V:V))/(MAX(V:V)-MIN(V:V)) -> 0.021346573 | Y6: =A7 -> 484 | Z6: =D7*P87*Y6^4 -> 1.9777766e+10 | AA6: =(Z6+Z7)/2*(Y7-Y6) -> 2.2315631e+10
A7: 484 | B7: =Messdaten!Q7-Messdaten!C7 -> 2224.497 | C7: =(B7-MIN(B:B))/(MAX(B:B)-MIN(B:B)) -> 0.024933177 | D7: =B7/SUM(B:B) -> 0.00037293217 | E7: 404 | F7: =Messdaten!T7-Messdaten!I7 -> 2552.4942 | G7: =(F7-MIN(F:F))/(MAX(F:F)-MIN(F:F)) -> 0.00097544652 | H7: =F7/MAX(F:F)*71000 -> 709.68395 | I7: 624 | J7: =Messdaten!W7-Messdaten!F7 -> 2469.896 | K7: =(J7-MIN(J:J))/(MAX(J:J)-MIN(J:J)) -> 0.0096827818 | L7: =J7/SUM(J:J) -> 0.00038372359 | M7: 404 | N7: =Messdaten!Z7-Messdaten!L7 -> 949.82988 | O7: =(N7-MIN(N:N))/(MAX(N:N)-MIN(N:N)) -> 0.0018128853 | P7: =N7/MAX(N:N)*250000 -> 345.27491 | Q7: 484 | R7: =Messdaten!AE7-Messdaten!C7 -> 2114.8339 | S7: =(R7-MIN(R:R))/(MAX(R:R)-MIN(R:R)) -> 0.021886113 | U7: 484 | V7: =Messdaten!AH7-Messdaten!C7 -> 2147.4857 | W7: =(V7-MIN(V:V))/(MAX(V:V)-MIN(V:V)) -> 0.026407436 | Y7: =A8 -> 485 | Z7: =D8*P88*Y7^4 -> 2.4853496e+10 | AA7: =(Z7+Z8)/2*(Y8-Y7) -> 2.86036e+10
A8: 485 | B8: =Messdaten!Q8-Messdaten!C8 -> 2812.4347 | C8: =(B8-MIN(B:B))/(MAX(B:B)-MIN(B:B)) -> 0.029800395 | D8: =B8/SUM(B:B) -> 0.00047149867 | E8: 405 | F8: =Messdaten!T8-Messdaten!I8 -> 2892.437 | G8: =(F8-MIN(F:F))/(MAX(F:F)-MIN(F:F)) -> 0.0023187889 | H8: =F8/MAX(F:F)*71000 -> 804.20011 | I8: 625 | J8: =Messdaten!W8-Messdaten!F8 -> 2857.2323 | K8: =(J8-MIN(J:J))/(MAX(J:J)-MIN(J:J)) -> 0.012540164 | L8: =J8/SUM(J:J) -> 0.00044390025 | M8: 405 | N8: =Messdaten!Z8-Messdaten!L8 -> 710.59646 | O8: =(N8-MIN(N:N))/(MAX(N:N)-MIN(N:N)) -> 0.0014651785 | P8: =N8/MAX(N:N)*250000 -> 258.31061 | Q8: 485 | R8: =Messdaten!AE8-Messdaten!C8 -> 2610.301 | S8: =(R8-MIN(R:R))/(MAX(R:R)-MIN(R:R)) -> 0.026687593 | U8: 485 | V8: =Messdaten!AH8-Messdaten!C8 -> 2573.3937 | W8: =(V8-MIN(V:V))/(MAX(V:V)-MIN(V:V)) -> 0.030658493 | Y8: =A9 -> 486 | Z8: =D9*P89*Y8^4 -> 3.2353703e+10 | AA8: =(Z8+Z9)/2*(Y9-Y8) -> 4.2313818e+10
A9: 486 | B9: =Messdaten!Q9-Messdaten!C9 -> 3761.0343 | C9: =(B9-MIN(B:B))/(MAX(B:B)-MIN(B:B)) -> 0.037653335 | D9: =B9/SUM(B:B) -> 0.00063052937 | E9: 406 | F9: =Messdaten!T9-Messdaten!I9 -> 3243.1649 | G9: =(F9-MIN(F:F))/(MAX(F:F)-MIN(F:F)) -> 0.0037047507 | H9: =F9/MAX(F:F)*71000 -> 901.71492 | I9: 626 | J9: =Messdaten!W9-Messdaten!F9 -> 3389.7165 | K9: =(J9-MIN(J:J))/(MAX(J:J)-MIN(J:J)) -> 0.016468303 | L9: =J9/SUM(J:J) -> 0.00052662712 | M9: 406 | N9: =Messdaten!Z9-Messdaten!L9 -> 606.0601 | O9: =(N9-MIN(N:N))/(MAX(N:N)-MIN(N:N)) -> 0.0013132432 | P9: =N9/MAX(N:N)*250000 -> 220.31035 | Q9: 486 | R9: =Messdaten!AE9-Messdaten!C9 -> 3579.0382 | S9: =(R9-MIN(R:R))/(MAX(R:R)-MIN(R:R)) -> 0.036075447 | U9: 486 | V9: =Messdaten!AH9-Messdaten!C9 -> 3400.0952 | W9: =(V9-MIN(V:V))/(MAX(V:V)-MIN(V:V)) -> 0.038909938 | Y9: =A10 -> 487 | Z9: =D10*P90*Y9^4 -> 5.2273933e+10 | AA9: =(Z9+Z10)/2*(Y10-Y9) -> 5.6828539e+10
A10: 487 | B10: =Messdaten!Q10-Messdaten!C10 -> 4745.2705 | C10: =(B10-MIN(B:B))/(MAX(B:B)-MIN(B:B)) -> 0.045801292 | D10: =B10/SUM(B:B) -> 0.00079553446 | E10: 407 | F10: =Messdaten!T10-Messdaten!I10 -> 3196.4041 | G10: =(F10-MIN(F:F))/(MAX(F:F)-MIN(F:F)) -> 0.0035199671 | H10: =F10/MAX(F:F)*71000 -> 888.71374 | I10: 627 | J10: =Messdaten!W10-Messdaten!F10 -> 4004.1901 | K10: =(J10-MIN(J:J))/(MAX(J:J)-MIN(J:J)) -> 0.021001278 | L10: =J10/SUM(J:J) -> 0.00062209187 | M10: 407 | N10: =Messdaten!Z10-Messdaten!L10 -> 348.03192 | O10: =(N10-MIN(N:N))/(MAX(N:N)-MIN(N:N)) -> 0.00093821966 | P10: =N10/MAX(N:N)*250000 -> 126.51391 | Q10: 487 | R10: =Messdaten!AE10-Messdaten!C10 -> 4405.8423 | S10: =(R10-MIN(R:R))/(MAX(R:R)-MIN(R:R)) -> 0.044087853 | U10: 487 | V10: =Messdaten!AH10-Messdaten!C10 -> 4215.8155 | W10: =(V10-MIN(V:V))/(MAX(V:V)-MIN(V:V)) -> 0.047051777 | Y10: =A11 -> 488 | Z10: =D11*P91*Y10^4 -> 6.1383146e+10 | AA10: =(Z10+Z11)/2*(Y11-Y10) -> 7.061327e+10
A11: 488 | B11: =Messdaten!Q11-Messdaten!C11 -> 5763.2833 | C11: =(B11-MIN(B:B))/(MAX(B:B)-MIN(B:B)) -> 0.054228867 | D11: =B11/SUM(B:B) -> 0.00096620213 | E11: 408 | F11: =Messdaten!T11-Messdaten!I11 -> 3400.3849 | G11: =(F11-MIN(F:F))/(MAX(F:F)-MIN(F:F)) -> 0.0043260323 | H11: =F11/MAX(F:F)*71000 -> 945.42764 | I11: 628 | J11: =Messdaten!W11-Messdaten!F11 -> 4973.1456 | K11: =(J11-MIN(J:J))/(MAX(J:J)-MIN(J:J)) -> 0.028149269 | L11: =J11/SUM(J:J) -> 0.00077262902 | M11: 408 | N11: =Messdaten!Z11-Messdaten!L11 -> 870.9676 | O11: =(N11-MIN(N:N))/(MAX(N:N)-MIN(N:N)) -> 0.0016982652 | P11: =N11/MAX(N:N)*250000 -> 316.6075 | Q11: 488 | R11: =Messdaten!AE11-Messdaten!C11 -> 5478.2714 | S11: =(R11-MIN(R:R))/(MAX(R:R)-MIN(R:R)) -> 0.054480566 | U11: 488 | V11: =Messdaten!AH11-Messdaten!C11 -> 5170.3203 | W11: =(V11-MIN(V:V))/(MAX(V:V)-MIN(V:V)) -> 0.056578847 | Y11: =A12 -> 489 | Z11: =D12*P92*Y11^4 -> 7.9843394e+10 | AA11: =(Z11+Z12)/2*(Y12-Y11) -> 8.6503172e+10
A12: 489 | B12: =Messdaten!Q12-Messdaten!C12 -> 7277.4691 | C12: =(B12-MIN(B:B))/(MAX(B:B)-MIN(B:B)) -> 0.06676399 | D12: =B12/SUM(B:B) -> 0.0012200522 | E12: 409 | F12: =Messdaten!T12-Messdaten!I12 -> 3622.3747 | G12: =(F12-MIN(F:F))/(MAX(F:F)-MIN(F:F)) -> 0.0052032633 | H12: =F12/MAX(F:F)*71000 -> 1007.1487 | I12: 629 | J12: =Messdaten!W12-Messdaten!F12 -> 5553.4646 | K12: =(J12-MIN(J:J))/(MAX(J:J)-MIN(J:J)) -> 0.032430285 | L12: =J12/SUM(J:J) -> 0.00086278751 | M12: 409 | N12: =Messdaten!Z12-Messdaten!L12 -> 590.02641 | O12: =(N12-MIN(N:N))/(MAX(N:N)-MIN(N:N)) -> 0.0012899395 | P12: =N12/MAX(N:N)*250000 -> 214.4819 | Q12: 489 | R12: =Messdaten!AE12-Messdaten!C12 -> 6633.7977 | S12: =(R12-MIN(R:R))/(MAX(R:R)-MIN(R:R)) -> 0.065678558 | U12: 489 | V12: =Messdaten!AH12-Messdaten!C12 -> 6554.3831 | W12: =(V12-MIN(V:V))/(MAX(V:V)-MIN(V:V)) -> 0.070393406 | Y12: =A13 -> 490 | Z12: =D13*P93*Y12^4 -> 9.3162949e+10 | AA12: =(Z12+Z13)/2*(Y13-Y12) -> 1.1594644e+11
A13: 490 | B13: =Messdaten!Q13-Messdaten!C13 -> 8964.9332 | C13: =(B13-MIN(B:B))/(MAX(B:B)-MIN(B:B)) -> 0.080733588 | D13: =B13/SUM(B:B) -> 0.0015029519 | E13: 410 | F13: =Messdaten!T13-Messdaten!I13 -> 3847.942 | G13: =(F13-MIN(F:F))/(MAX(F:F)-MIN(F:F)) -> 0.0060946314 | H13: =F13/MAX(F:F)*71000 -> 1069.8644 | I13: 630 | J13: =Messdaten!W13-Messdaten!F13 -> 6805.6204 | K13: =(J13-MIN(J:J))/(MAX(J:J)-MIN(J:J)) -> 0.041667446 | L13: =J13/SUM(J:J) -> 0.0010573227 | M13: 410 | N13: =Messdaten!Z13-Messdaten!L13 -> 145.85345 | O13: =(N13-MIN(N:N))/(MAX(N:N)-MIN(N:N)) -> 0.00064436927 | P13: =N13/MAX(N:N)*250000 -> 53.019534 | Q13: 490 | R13: =Messdaten!AE13-Messdaten!C13 -> 8308.6704 | S13: =(R13-MIN(R:R))/(MAX(R:R)-MIN(R:R)) -> 0.081909441 | U13: 490 | V13: =Messdaten!AH13-Messdaten!C13 -> 8000.1676 | W13: =(V13-MIN(V:V))/(MAX(V:V)-MIN(V:V)) -> 0.08482402 | Y13: =A14 -> 491 | Z13: =D14*P94*Y13^4 -> 1.3872993e+11 | AA13: =(Z13+Z14)/2*(Y14-Y13) -> 1.518235e+11
A14: 491 | B14: =Messdaten!Q14-Messdaten!C14 -> 10771.94 | C14: =(B14-MIN(B:B))/(MAX(B:B)-MIN(B:B)) -> 0.095692816 | D14: =B14/SUM(B:B) -> 0.0018058927 | E14: 411 | F14: =Messdaten!T14-Messdaten!I14 -> 4059.5204 | G14: =(F14-MIN(F:F))/(MAX(F:F)-MIN(F:F)) -> 0.0069307197 | H14: =F14/MAX(F:F)*71000 -> 1128.6907 | I14: 631 | J14: =Messdaten!W14-Messdaten!F14 -> 7840.265 | K14: =(J14-MIN(J:J))/(MAX(J:J)-MIN(J:J)) -> 0.049300025 | L14: =J14/SUM(J:J) -> 0.0012180653 | M14: 411 | N14: =Messdaten!Z14-Messdaten!L14 -> 601.83341 | O14: =(N14-MIN(N:N))/(MAX(N:N)-MIN(N:N)) -> 0.0013071 | P14: =N14/MAX(N:N)*250000 -> 218.77389 | Q14: 491 | R14: =Messdaten!AE14-Messdaten!C14 -> 9960.1508 | S14: =(R14-MIN(R:R))/(MAX(R:R)-MIN(R:R)) -> 0.097913633 | U14: 491 | V14: =Messdaten!AH14-Messdaten!C14 -> 9528.4079 | W14: =(V14-MIN(V:V))/(MAX(V:V)-MIN(V:V)) -> 0.10007764 | Y14: =A15 -> 492 | Z14: =D15*P95*Y14^4 -> 1.6491706e+11 | AA14: =(Z14+Z15)/2*(Y15-Y14) -> 1.8934105e+11
A15: 492 | B15: =Messdaten!Q15-Messdaten!C15 -> 13147.007 | C15: =(B15-MIN(B:B))/(MAX(B:B)-MIN(B:B)) -> 0.11535471 | D15: =B15/SUM(B:B) -> 0.0022040677 | E15: 412 | F15: =Messdaten!T15-Messdaten!I15 -> 4350.5888 | G15: =(F15-MIN(F:F))/(MAX(F:F)-MIN(F:F)) -> 0.0080809265 | H15: =F15/MAX(F:F)*71000 -> 1209.618 | I15: 632 | J15: =Messdaten!W15-Messdaten!F15 -> 9249.2223 | K15: =(J15-MIN(J:J))/(MAX(J:J)-MIN(J:J)) -> 0.059693911 | L15: =J15/SUM(J:J) -> 0.0014369613 | M15: 412 | N15: =Messdaten!Z15-Messdaten!L15 -> 477.80067 | O15: =(N15-MIN(N:N))/(MAX(N:N)-MIN(N:N)) -> 0.0011268283 | P15: =N15/MAX(N:N)*250000 -> 173.68646 | Q15: 492 | R15: =Messdaten!AE15-Messdaten!C15 -> 12101.797 | S15: =(R15-MIN(R:R))/(MAX(R:R)-MIN(R:R)) -> 0.11866794 | U15: 492 | V15: =Messdaten!AH15-Messdaten!C15 -> 11578.048 | W15: =(V15-MIN(V:V))/(MAX(V:V)-MIN(V:V)) -> 0.12053544 | Y15: =A16 -> 493 | Z15: =D16*P96*Y15^4 -> 2.1376504e+11 | AA15: =(Z15+Z16)/2*(Y16-Y15) -> 2.3372294e+11
... A113: 590 | B113: =Messdaten!Q113-Messdaten!C113 -> 11308.022 | C113: =(B113-MIN(B:B))/(MAX(B:B)-MIN(B:B)) -> 0.10013075 | D113: =B113/SUM(B:B) -> 0.0018957657 | E113: 510 | F113: =Messdaten!T113-Messdaten!I113 -> 66761.637 | G113: =(F113-MIN(F:F))/(MAX(F:F)-MIN(F:F)) -> 0.25470892 | H113: =F113/MAX(F:F)*71000 -> 18562.104 | I113: 730 | J113: =Messdaten!W113-Messdaten!F113 -> 21154.112 | K113: =(J113-MIN(J:J))/(MAX(J:J)-MIN(J:J)) -> 0.14751635 | L113: =J113/SUM(J:J) -> 0.0032865075 | M113: 510 | N113: =Messdaten!Z113-Messdaten!L113 -> 8073.0527 | O113: =(N113-MIN(N:N))/(MAX(N:N)-MIN(N:N)) -> 0.012165925 | P113: =N113/MAX(N:N)*250000 -> 2934.6546 | Q113: 590 | R113: =Messdaten!AE113-Messdaten!C113 -> 8560.1619 | S113: =(R113-MIN(R:R))/(MAX(R:R)-MIN(R:R)) -> 0.084346598 | U113: 590 | V113: =Messdaten!AH113-Messdaten!C113 -> 8265.5039 | W113: =(V113-MIN(V:V))/(MAX(V:V)-MIN(V:V)) -> 0.087472386 | Y113: =A114 -> 591 | Z113: =D114*P194*Y113^4 -> 1.5434548e+13 | AA113: =(Z113+Z114)/2*(Y114-Y113) -> 1.5274805e+13
A114: 591 | B114: =Messdaten!Q114-Messdaten!C114 -> 11293.609 | C114: =(B114-MIN(B:B))/(MAX(B:B)-MIN(B:B)) -> 0.10001143 | D114: =B114/SUM(B:B) -> 0.0018933494 | I114: 731 | J114: =Messdaten!W114-Messdaten!F114 -> 20250.647 | K114: =(J114-MIN(J:J))/(MAX(J:J)-MIN(J:J)) -> 0.14085148 | L114: =J114/SUM(J:J) -> 0.0031461451 | M114: 511 | N114: =Messdaten!Z114-Messdaten!L114 -> 8101.7176 | O114: =(N114-MIN(N:N))/(MAX(N:N)-MIN(N:N)) -> 0.012207588 | P114: =N114/MAX(N:N)*250000 -> 2945.0746 | Q114: 591 | R114: =Messdaten!AE114-Messdaten!C114 -> 8324.7572 | S114: =(R114-MIN(R:R))/(MAX(R:R)-MIN(R:R)) -> 0.082065335 | U114: 591 | V114: =Messdaten!AH114-Messdaten!C114 -> 8100.2855 | W114: =(V114-MIN(V:V))/(MAX(V:V)-MIN(V:V)) -> 0.085823313 | Y114: =A115 -> 592 | Z114: =D115*P195*Y114^4 -> 1.5115063e+13 | AA114: =(Z114+Z115)/2*(Y115-Y114) -> 1.5064847e+13
A115: 592 | B115: =Messdaten!Q115-Messdaten!C115 -> 10664.996 | C115: =(B115-MIN(B:B))/(MAX(B:B)-MIN(B:B)) -> 0.094807486 | D115: =B115/SUM(B:B) -> 0.0017879638 | I115: 732 | J115: =Messdaten!W115-Messdaten!F115 -> 19496.41 | K115: =(J115-MIN(J:J))/(MAX(J:J)-MIN(J:J)) -> 0.13528747 | L115: =J115/SUM(J:J) -> 0.0030289666 | M115: 512 | N115: =Messdaten!Z115-Messdaten!L115 -> 8710.3907 | O115: =(N115-MIN(N:N))/(MAX(N:N)-MIN(N:N)) -> 0.013092246 | P115: =N115/MAX(N:N)*250000 -> 3166.3348 | Q115: 592 | R115: =Messdaten!AE115-Messdaten!C115 -> 7914.8623 | S115: =(R115-MIN(R:R))/(MAX(R:R)-MIN(R:R)) -> 0.078093119 | U115: 592 | V115: =Messdaten!AH115-Messdaten!C115 -> 7670.2784 | W115: =(V115-MIN(V:V))/(MAX(V:V)-MIN(V:V)) -> 0.081531341 | Y115: =A116 -> 593 | Z115: =D116*P196*Y115^4 -> 1.501463e+13 | AA115: =(Z115+Z116)/2*(Y116-Y115) -> 1.4897142e+13
A116: 593 | B116: =Messdaten!Q116-Messdaten!C116 -> 10241.425 | C116: =(B116-MIN(B:B))/(MAX(B:B)-MIN(B:B)) -> 0.09130097 | D116: =B116/SUM(B:B) -> 0.001716953 | I116: 733 | J116: =Messdaten!W116-Messdaten!F116 -> 19458.126 | K116: =(J116-MIN(J:J))/(MAX(J:J)-MIN(J:J)) -> 0.13500505 | L116: =J116/SUM(J:J) -> 0.0030230189 | M116: 513 | N116: =Messdaten!Z116-Messdaten!L116 -> 8707.147 | O116: =(N116-MIN(N:N))/(MAX(N:N)-MIN(N:N)) -> 0.013087531 | P116: =N116/MAX(N:N)*250000 -> 3165.1557 | Q116: 593 | R116: =Messdaten!AE116-Messdaten!C116 -> 7733.7654 | S116: =(R116-MIN(R:R))/(MAX(R:R)-MIN(R:R)) -> 0.076338142 | U116: 593 | V116: =Messdaten!AH116-Messdaten!C116 -> 7479.8416 | W116: =(V116-MIN(V:V))/(MAX(V:V)-MIN(V:V)) -> 0.07963056 | Y116: =A117 -> 594 | Z116: =D117*P197*Y116^4 -> 1.4779654e+13 | AA116: =(Z116+Z117)/2*(Y117-Y116) -> 1.4581468e+13
A117: 594 | B117: =Messdaten!Q117-Messdaten!C117 -> 9820.2194 | C117: =(B117-MIN(B:B))/(MAX(B:B)-MIN(B:B)) -> 0.087814038 | D117: =B117/SUM(B:B) -> 0.0016463388 | I117: 734 | J117: =Messdaten!W117-Messdaten!F117 -> 18606.748 | K117: =(J117-MIN(J:J))/(MAX(J:J)-MIN(J:J)) -> 0.12872443 | L117: =J117/SUM(J:J) -> 0.0028907486 | M117: 514 | N117: =Messdaten!Z117-Messdaten!L117 -> 9436.9302 | O117: =(N117-MIN(N:N))/(MAX(N:N)-MIN(N:N)) -> 0.014148213 | P117: =N117/MAX(N:N)*250000 -> 3430.4409 | Q117: 594 | R117: =Messdaten!AE117-Messdaten!C117 -> 7263.2174 | S117: =(R117-MIN(R:R))/(MAX(R:R)-MIN(R:R)) -> 0.071778148 | U117: 594 | V117: =Messdaten!AH117-Messdaten!C117 -> 7130.4872 | W117: =(V117-MIN(V:V))/(MAX(V:V)-MIN(V:V)) -> 0.076143596 | Y117: =A118 -> 595 | Z117: =D118*P198*Y117^4 -> 1.4383283e+13 | AA117: =(Z117+Z118)/2*(Y118-Y117) -> 1.4252798e+13
A118: 595 | B118: =Messdaten!Q118-Messdaten!C118 -> 9352.2815 | C118: =(B118-MIN(B:B))/(MAX(B:B)-MIN(B:B)) -> 0.083940234 | D118: =B118/SUM(B:B) -> 0.00156789 | I118: 735 | J118: =Messdaten!W118-Messdaten!F118 -> 17366.336 | K118: =(J118-MIN(J:J))/(MAX(J:J)-MIN(J:J)) -> 0.11957391 | L118: =J118/SUM(J:J) -> 0.0026980379 | M118: 515 | N118: =Messdaten!Z118-Messdaten!L118 -> 9805.1361 | O118: =(N118-MIN(N:N))/(MAX(N:N)-MIN(N:N)) -> 0.014683371 | P118: =N118/MAX(N:N)*250000 -> 3564.2883 | Q118: 595 | R118: =Messdaten!AE118-Messdaten!C118 -> 7141.4302 | S118: =(R118-MIN(R:R))/(MAX(R:R)-MIN(R:R)) -> 0.070597932 | U118: 595 | V118: =Messdaten!AH118-Messdaten!C118 -> 6922.3933 | W118: =(V118-MIN(V:V))/(MAX(V:V)-MIN(V:V)) -> 0.074066577 | Y118: =A119 -> 596 | Z118: =D119*P199*Y118^4 -> 1.4122314e+13 | AA118: =(Z118+Z119)/2*(Y119-Y118) -> 1.3977717e+13
A119: 596 | B119: =Messdaten!Q119-Messdaten!C119 -> 9153.807 | C119: =(B119-MIN(B:B))/(MAX(B:B)-MIN(B:B)) -> 0.082297172 | D119: =B119/SUM(B:B) -> 0.0015346162 | I119: 736 | J119: =Messdaten!W119-Messdaten!F119 -> 16856.484 | K119: =(J119-MIN(J:J))/(MAX(J:J)-MIN(J:J)) -> 0.11581272 | L119: =J119/SUM(J:J) -> 0.0026188272 | M119: 516 | N119: =Messdaten!Z119-Messdaten!L119 -> 10673.531 | O119: =(N119-MIN(N:N))/(MAX(N:N)-MIN(N:N)) -> 0.015945514 | P119: =N119/MAX(N:N)*250000 -> 3879.9604 | Q119: 596 | R119: =Messdaten!AE119-Messdaten!C119 -> 7040.615 | S119: =(R119-MIN(R:R))/(MAX(R:R)-MIN(R:R)) -> 0.06962095 | U119: 596 | V119: =Messdaten!AH119-Messdaten!C119 -> 6705.9704 | W119: =(V119-MIN(V:V))/(MAX(V:V)-MIN(V:V)) -> 0.071906424 | Y119: =A120 -> 597 | Z119: =D120*P200*Y119^4 -> 1.383312e+13 | AA119: =(Z119+Z120)/2*(Y120-Y119) -> 1.3826973e+13
A120: 597 | B120: =Messdaten!Q120-Messdaten!C120 -> 8605.2542 | C120: =(B120-MIN(B:B))/(MAX(B:B)-MIN(B:B)) -> 0.077756001 | D120: =B120/SUM(B:B) -> 0.0014426525 | I120: 737 | J120: =Messdaten!W120-Messdaten!F120 -> 16483.64 | K120: =(J120-MIN(J:J))/(MAX(J:J)-MIN(J:J)) -> 0.11306225 | L120: =J120/SUM(J:J) -> 0.0025609019 | M120: 517 | N120: =Messdaten!Z120-Messdaten!L120 -> 10526.684 | O120: =(N120-MIN(N:N))/(MAX(N:N)-MIN(N:N)) -> 0.015732083 | P120: =N120/MAX(N:N)*250000 -> 3826.5797 | Q120: 597 | R120: =Messdaten!AE120-Messdaten!C120 -> 6537.4638 | S120: =(R120-MIN(R:R))/(MAX(R:R)-MIN(R:R)) -> 0.064745004 | U120: 597 | V120: =Messdaten!AH120-Messdaten!C120 -> 6378.7887 | W120: =(V120-MIN(V:V))/(MAX(V:V)-MIN(V:V)) -> 0.068640769 | Y120: =A121 -> 598 | Z120: =D121*P201*Y120^4 -> 1.3820826e+13 | AA120: =(Z120+Z121)/2*(Y121-Y120) -> 1.3392488e+13
A121: 598 | B121: =Messdaten!Q121-Messdaten!C121 -> 8543.8186 | C121: =(B121-MIN(B:B))/(MAX(B:B)-MIN(B:B)) -> 0.077247409 | D121: =B121/SUM(B:B) -> 0.0014323529 | I121: 738 | J121: =Messdaten!W121-Messdaten!F121 -> 16445.355 | K121: =(J121-MIN(J:J))/(MAX(J:J)-MIN(J:J)) -> 0.11277982 | L121: =J121/SUM(J:J) -> 0.002554954 | M121: 518 | N121: =Messdaten!Z121-Messdaten!L121 -> 10820.293 | O121: =(N121-MIN(N:N))/(MAX(N:N)-MIN(N:N)) -> 0.016158822 | P121: =N121/MAX(N:N)*250000 -> 3933.3105 | Q121: 598 | R121: =Messdaten!AE121-Messdaten!C121 -> 6413.7183 | S121: =(R121-MIN(R:R))/(MAX(R:R)-MIN(R:R)) -> 0.063545809 | U121: 598 | V121: =Messdaten!AH121-Messdaten!C121 -> 6411.934 | W121: =(V121-MIN(V:V))/(MAX(V:V)-MIN(V:V)) -> 0.068971598 | Y121: =A122 -> 599 | Z121: =D122*P202*Y121^4 -> 1.296415e+13 | AA121: =(Z121+Z122)/2*(Y122-Y121) -> 1.2950005e+13
A122: 599 | B122: =Messdaten!Q122-Messdaten!C122 -> 7936.1811 | C122: =(B122-MIN(B:B))/(MAX(B:B)-MIN(B:B)) -> 0.072217108 | D122: =B122/SUM(B:B) -> 0.0013304838 | I122: 739 | J122: =Messdaten!W122-Messdaten!F122 -> 15761.354 | K122: =(J122-MIN(J:J))/(MAX(J:J)-MIN(J:J)) -> 0.10773394 | L122: =J122/SUM(J:J) -> 0.0024486875 | M122: 519 | N122: =Messdaten!Z122-Messdaten!L122 -> 11444.679 | O122: =(N122-MIN(N:N))/(MAX(N:N)-MIN(N:N)) -> 0.017066317 | P122: =N122/MAX(N:N)*250000 -> 4160.2824 | Q122: 599 | R122: =Messdaten!AE122-Messdaten!C122 -> 6422.6125 | S122: =(R122-MIN(R:R))/(MAX(R:R)-MIN(R:R)) -> 0.063632001 | U122: 599 | V122: =Messdaten!AH122-Messdaten!C122 -> 6078.7814 | W122: =(V122-MIN(V:V))/(MAX(V:V)-MIN(V:V)) -> 0.065646347 | Y122: =A123 -> 600 | Z122: =D123*P203*Y122^4 -> 1.293586e+13 | AA122: =(Z122+Z123)/2*(Y123-Y122) -> 1.280756e+13
A123: 600 | B123: =Messdaten!Q123-Messdaten!C123 -> 7727.1989 | C123: =(B123-MIN(B:B))/(MAX(B:B)-MIN(B:B)) -> 0.070487058 | D123: =B123/SUM(B:B) -> 0.0012954484 | I123: 740 | J123: =Messdaten!W123-Messdaten!F123 -> 15747.803 | K123: =(J123-MIN(J:J))/(MAX(J:J)-MIN(J:J)) -> 0.10763398 | L123: =J123/SUM(J:J) -> 0.0024465823 | M123: 520 | N123: =Messdaten!Z123-Messdaten!L123 -> 11937.419 | O123: =(N123-MIN(N:N))/(MAX(N:N)-MIN(N:N)) -> 0.017782475 | P123: =N123/MAX(N:N)*250000 -> 4339.3994 | Q123: 600 | R123: =Messdaten!AE123-Messdaten!C123 -> 6096.6556 | S123: =(R123-MIN(R:R))/(MAX(R:R)-MIN(R:R)) -> 0.060473213 | U123: 600 | V123: =Messdaten!AH123-Messdaten!C123 -> 5819.6975 | W123: =(V123-MIN(V:V))/(MAX(V:V)-MIN(V:V)) -> 0.063060388 | Y123: =A124 -> 601 | Z123: =D124*P204*Y123^4 -> 1.267926e+13 | AA123: =(Z123+Z124)/2*(Y124-Y123) -> 1.248123e+13
A124: 601 | B124: =Messdaten!Q124-Messdaten!C124 -> 7619.4052 | C124: =(B124-MIN(B:B))/(MAX(B:B)-MIN(B:B)) -> 0.069594692 | D124: =B124/SUM(B:B) -> 0.001277377 | I124: 741 | J124: =Messdaten!W124-Messdaten!F124 -> 15745.907 | K124: =(J124-MIN(J:J))/(MAX(J:J)-MIN(J:J)) -> 0.10761999 | L124: =J124/SUM(J:J) -> 0.0024462877 | M124: 521 | N124: =Messdaten!Z124-Messdaten!L124 -> 11845.009 | O124: =(N124-MIN(N:N))/(MAX(N:N)-MIN(N:N)) -> 0.017648166 | P124: =N124/MAX(N:N)*250000 -> 4305.8075 | Q124: 601 | R124: =Messdaten!AE124-Messdaten!C124 -> 5844.2334 | S124: =(R124-MIN(R:R))/(MAX(R:R)-MIN(R:R)) -> 0.058027036 | U124: 601 | V124: =Messdaten!AH124-Messdaten!C124 -> 5668.8896 | W124: =(V124-MIN(V:V))/(MAX(V:V)-MIN(V:V)) -> 0.061555149 | Y124: =A125 -> 602 | Z124: =D125*P205*Y124^4 -> 1.2283199e+13 | AA124: =(Z124+Z125)/2*(Y125-Y124) -> 1.2327152e+13
A125: 602 | B125: =Messdaten!Q125-Messdaten!C125 -> 7314.6564 | C125: =(B125-MIN(B:B))/(MAX(B:B)-MIN(B:B)) -> 0.067071842 | D125: =B125/SUM(B:B) -> 0.0012262865 | I125: 742 | J125: =Messdaten!W125-Messdaten!F125 -> 14231.052 | K125: =(J125-MIN(J:J))/(MAX(J:J)-MIN(J:J)) -> 0.0964449 | L125: =J125/SUM(J:J) -> 0.0022109395 | M125: 522 | N125: =Messdaten!Z125-Messdaten!L125 -> 13091.025 | O125: =(N125-MIN(N:N))/(MAX(N:N)-MIN(N:N)) -> 0.019459151 | P125: =N125/MAX(N:N)*250000 -> 4758.7495 | Q125: 602 | R125: =Messdaten!AE125-Messdaten!C125 -> 5496.0679 | S125: =(R125-MIN(R:R))/(MAX(R:R)-MIN(R:R)) -> 0.054653028 | U125: 602 | V125: =Messdaten!AH125-Messdaten!C125 -> 5330.3381 | W125: =(V125-MIN(V:V))/(MAX(V:V)-MIN(V:V)) -> 0.058176011 | Y125: =A126 -> 603 | Z125: =D126*P206*Y125^4 -> 1.2371104e+13 | AA125: =(Z125+Z126)/2*(Y126-Y125) -> 1.2042545e+13
... A181: 658 | B181: =Messdaten!Q181-Messdaten!C181 -> 967.11801 | C181: =(B181-MIN(B:B))/(MAX(B:B)-MIN(B:B)) -> 0.01452402 | D181: =B181/SUM(B:B) -> 0.00016213527 | I181: 798 | J181: =Messdaten!W181-Messdaten!F181 -> 2609.6305 | K181: =(J181-MIN(J:J))/(MAX(J:J)-MIN(J:J)) -> 0.010713604 | L181: =J181/SUM(J:J) -> 0.00040543278 | M181: 578 | N181: =Messdaten!Z181-Messdaten!L181 -> 110746.38 | O181: =(N181-MIN(N:N))/(MAX(N:N)-MIN(N:N)) -> 0.16139347 | P181: =N181/MAX(N:N)*250000 -> 40257.678 | Q181: 658 | R181: =Messdaten!AE181-Messdaten!C181 -> 38897.348 | S181: =(R181-MIN(R:R))/(MAX(R:R)-MIN(R:R)) -> 0.37833868 | U181: 658 | V181: =Messdaten!AH181-Messdaten!C181 -> 16393.495 | W181: =(V181-MIN(V:V))/(MAX(V:V)-MIN(V:V)) -> 0.1685992 | Y181: =A182 -> 659 | Z181: =D182*P262*Y181^4 -> 4.3064143e+12 | AA181: =(Z181+Z182)/2*(Y182-Y181) -> 3.8319059e+12
A182: 659 | B182: =Messdaten!Q182-Messdaten!C182 -> 1002.0961 | C182: =(B182-MIN(B:B))/(MAX(B:B)-MIN(B:B)) -> 0.014813584 | D182: =B182/SUM(B:B) -> 0.00016799927 | I182: 799 | J182: =Messdaten!W182-Messdaten!F182 -> 1836.6897 | K182: =(J182-MIN(J:J))/(MAX(J:J)-MIN(J:J)) -> 0.0050116159 | L182: =J182/SUM(J:J) -> 0.00028534853 | M182: 579 | N182: =Messdaten!Z182-Messdaten!L182 -> 114129.73 | O182: =(N182-MIN(N:N))/(MAX(N:N)-MIN(N:N)) -> 0.1663109 | P182: =N182/MAX(N:N)*250000 -> 41487.567 | Q182: 659 | R182: =Messdaten!AE182-Messdaten!C182 -> 39978.29 | S182: =(R182-MIN(R:R))/(MAX(R:R)-MIN(R:R)) -> 0.38881389 | U182: 659 | V182: =Messdaten!AH182-Messdaten!C182 -> 16715.998 | W182: =(V182-MIN(V:V))/(MAX(V:V)-MIN(V:V)) -> 0.17181816 | Y182: =A183 -> 660 | Z182: =D183*P263*Y182^4 -> 3.3573976e+12
A183: 660 | B183: =Messdaten!Q183-Messdaten!C183 -> 841.01577 | C183: =(B183-MIN(B:B))/(MAX(B:B)-MIN(B:B)) -> 0.013480088 | D183: =B183/SUM(B:B) -> 0.0001409945 | I183: 800 | J183: =Messdaten!W183-Messdaten!F183 -> 2946.1024 | K183: =(J183-MIN(J:J))/(MAX(J:J)-MIN(J:J)) -> 0.01319576 | L183: =J183/SUM(J:J) -> 0.00045770713 | M183: 580 | N183: =Messdaten!Z183-Messdaten!L183 -> 121444.07 | O183: =(N183-MIN(N:N))/(MAX(N:N)-MIN(N:N)) -> 0.17694171 | P183: =N183/MAX(N:N)*250000 -> 44146.421 | Q183: 660 | R183: =Messdaten!AE183-Messdaten!C183 -> 40922.164 | S183: =(R183-MIN(R:R))/(MAX(R:R)-MIN(R:R)) -> 0.3979608 | U183: 660 | V183: =Messdaten!AH183-Messdaten!C183 -> 17185.616 | W183: =(V183-MIN(V:V))/(MAX(V:V)-MIN(V:V)) -> 0.1765055
A184: 661 | B184: =Messdaten!Q184-Messdaten!C184 -> 781.02418 | C184: =(B184-MIN(B:B))/(MAX(B:B)-MIN(B:B)) -> 0.01298345 | D184: =B184/SUM(B:B) -> 0.00013093703 | M184: 581 | N184: =Messdaten!Z184-Messdaten!L184 -> 126305.81 | O184: =(N184-MIN(N:N))/(MAX(N:N)-MIN(N:N)) -> 0.18400787 | P184: =N184/MAX(N:N)*250000 -> 45913.724 | Q184: 661 | R184: =Messdaten!AE184-Messdaten!C184 -> 42476.249 | S184: =(R184-MIN(R:R))/(MAX(R:R)-MIN(R:R)) -> 0.41302115 | U184: 661 | V184: =Messdaten!AH184-Messdaten!C184 -> 17605.782 | W184: =(V184-MIN(V:V))/(MAX(V:V)-MIN(V:V)) -> 0.18069924
A185: 662 | B185: =Messdaten!Q185-Messdaten!C185 -> 763.98982 | C185: =(B185-MIN(B:B))/(MAX(B:B)-MIN(B:B)) -> 0.012842432 | D185: =B185/SUM(B:B) -> 0.00012808126 | M185: 582 | N185: =Messdaten!Z185-Messdaten!L185 -> 132470.66 | O185: =(N185-MIN(N:N))/(MAX(N:N)-MIN(N:N)) -> 0.19296799 | P185: =N185/MAX(N:N)*250000 -> 48154.722 | Q185: 662 | R185: =Messdaten!AE185-Messdaten!C185 -> 42911.268 | S185: =(R185-MIN(R:R))/(MAX(R:R)-MIN(R:R)) -> 0.41723684 | U185: 662 | V185: =Messdaten!AH185-Messdaten!C185 -> 17815.174 | W185: =(V185-MIN(V:V))/(MAX(V:V)-MIN(V:V)) -> 0.18278922
A186: 663 | B186: =Messdaten!Q186-Messdaten!C186 -> 866.70058 | C186: =(B186-MIN(B:B))/(MAX(B:B)-MIN(B:B)) -> 0.013692718 | D186: =B186/SUM(B:B) -> 0.0001453005 | M186: 583 | N186: =Messdaten!Z186-Messdaten!L186 -> 139212.51 | O186: =(N186-MIN(N:N))/(MAX(N:N)-MIN(N:N)) -> 0.20276673 | P186: =N186/MAX(N:N)*250000 -> 50605.468 | Q186: 663 | R186: =Messdaten!AE186-Messdaten!C186 -> 43759.288 | S186: =(R186-MIN(R:R))/(MAX(R:R)-MIN(R:R)) -> 0.42545484 | U186: 663 | V186: =Messdaten!AH186-Messdaten!C186 -> 18018.392 | W186: =(V186-MIN(V:V))/(MAX(V:V)-MIN(V:V)) -> 0.18481757
A187: 664 | B187: =Messdaten!Q187-Messdaten!C187 -> 902.1582 | C187: =(B187-MIN(B:B))/(MAX(B:B)-MIN(B:B)) -> 0.013986253 | D187: =B187/SUM(B:B) -> 0.00015124489 | M187: 584 | N187: =Messdaten!Z187-Messdaten!L187 -> 144275.23 | O187: =(N187-MIN(N:N))/(MAX(N:N)-MIN(N:N)) -> 0.210125 | P187: =N187/MAX(N:N)*250000 -> 52445.831 | Q187: 664 | R187: =Messdaten!AE187-Messdaten!C187 -> 44086.032 | S187: =(R187-MIN(R:R))/(MAX(R:R)-MIN(R:R)) -> 0.42862125 | U187: 664 | V187: =Messdaten!AH187-Messdaten!C187 -> 18264.987 | W187: =(V187-MIN(V:V))/(MAX(V:V)-MIN(V:V)) -> 0.18727888
A188: 665 | B188: =Messdaten!Q188-Messdaten!C188 -> 785.14783 | C188: =(B188-MIN(B:B))/(MAX(B:B)-MIN(B:B)) -> 0.013017587 | D188: =B188/SUM(B:B) -> 0.00013162836 | M188: 585 | N188: =Messdaten!Z188-Messdaten!L188 -> 151355.15 | O188: =(N188-MIN(N:N))/(MAX(N:N)-MIN(N:N)) -> 0.2204151 | P188: =N188/MAX(N:N)*250000 -> 55019.47 | Q188: 665 | R188: =Messdaten!AE188-Messdaten!C188 -> 44052.715 | S188: =(R188-MIN(R:R))/(MAX(R:R)-MIN(R:R)) -> 0.42829839 | U188: 665 | V188: =Messdaten!AH188-Messdaten!C188 -> 18275.904 | W188: =(V188-MIN(V:V))/(MAX(V:V)-MIN(V:V)) -> 0.18738784
A189: 666 | B189: =Messdaten!Q189-Messdaten!C189 -> 615.57276 | C189: =(B189-MIN(B:B))/(MAX(B:B)-MIN(B:B)) -> 0.011613768 | D189: =B189/SUM(B:B) -> 0.00010319946 | M189: 586 | N189: =Messdaten!Z189-Messdaten!L189 -> 156535.85 | O189: =(N189-MIN(N:N))/(MAX(N:N)-MIN(N:N)) -> 0.22794483 | P189: =N189/MAX(N:N)*250000 -> 56902.717 | Q189: 666 | R189: =Messdaten!AE189-Messdaten!C189 -> 44077.408 | S189: =(R189-MIN(R:R))/(MAX(R:R)-MIN(R:R)) -> 0.42853769 | U189: 666 | V189: =Messdaten!AH189-Messdaten!C189 -> 18482.244 | W189: =(V189-MIN(V:V))/(MAX(V:V)-MIN(V:V)) -> 0.18944736
A190: 667 | B190: =Messdaten!Q190-Messdaten!C190 -> 685.99363 | C190: =(B190-MIN(B:B))/(MAX(B:B)-MIN(B:B)) -> 0.012196744 | D190: =B190/SUM(B:B) -> 0.00011500537 | M190: 587 | N190: =Messdaten!Z190-Messdaten!L190 -> 162173.14 | O190: =(N190-MIN(N:N))/(MAX(N:N)-MIN(N:N)) -> 0.2361382 | P190: =N190/MAX(N:N)*250000 -> 58951.943 | Q190: 667 | R190: =Messdaten!AE190-Messdaten!C190 -> 44466.996 | S190: =(R190-MIN(R:R))/(MAX(R:R)-MIN(R:R)) -> 0.43231311 | U190: 667 | V190: =Messdaten!AH190-Messdaten!C190 -> 17920.646 | W190: =(V190-MIN(V:V))/(MAX(V:V)-MIN(V:V)) -> 0.18384195
A191: 668 | B191: =Messdaten!Q191-Messdaten!C191 -> 768.5379 | C191: =(B191-MIN(B:B))/(MAX(B:B)-MIN(B:B)) -> 0.012880083 | D191: =B191/SUM(B:B) -> 0.00012884374 | M191: 588 | N191: =Messdaten!Z191-Messdaten!L191 -> 167734.95 | O191: =(N191-MIN(N:N))/(MAX(N:N)-MIN(N:N)) -> 0.24422184 | P191: =N191/MAX(N:N)*250000 -> 60973.729 | Q191: 668 | R191: =Messdaten!AE191-Messdaten!C191 -> 43569.922 | S191: =(R191-MIN(R:R))/(MAX(R:R)-MIN(R:R)) -> 0.42361973 | U191: 668 | V191: =Messdaten!AH191-Messdaten!C191 -> 18037.505 | W191: =(V191-MIN(V:V))/(MAX(V:V)-MIN(V:V)) -> 0.18500834
A192: 669 | B192: =Messdaten!Q192-Messdaten!C192 -> 585.51826 | C192: =(B192-MIN(B:B))/(MAX(B:B)-MIN(B:B)) -> 0.011364963 | D192: =B192/SUM(B:B) -> 9.8160885e-05 | M192: 589 | N192: =Messdaten!Z192-Messdaten!L192 -> 173740.02 | O192: =(N192-MIN(N:N))/(MAX(N:N)-MIN(N:N)) -> 0.25294975 | P192: =N192/MAX(N:N)*250000 -> 63156.649 | Q192: 669 | R192: =Messdaten!AE192-Messdaten!C192 -> 42329.122 | S192: =(R192-MIN(R:R))/(MAX(R:R)-MIN(R:R)) -> 0.41159537 | U192: 669 | V192: =Messdaten!AH192-Messdaten!C192 -> 17906.686 | W192: =(V192-MIN(V:V))/(MAX(V:V)-MIN(V:V)) -> 0.18370261
...
